Workbook

Sheet Resumen
B2: Resumen de Ponderacion y Horas
B4: Curso | C4: 722 - Teoría de Sistemas 1
B5: Semestre que aplica | C5: Segundo Semestre 2026
B6: Total de Puntos del Laboratorio
A8: * Esta sección se auto completa al momento en que se llene a la información de la planificación
A9: ** Tomar como base la distribución realizada por el coordinador del area del curso en el documento de criterios y expectativas
A10: Tipo de Actividad | B10: Ponderacion | C10: Horas utilizadas | D10: Aspectos clave que debe abordar | G10: Valor Maximo Recomendado
A11: Actividades durante el peridodo de laboratorio | B11: =S.2!C7+S.3!C7+S.4!C7+S.5!C7+S.6!C7+S.7!C7+S.8!C7+S.9!C7+S.10!C7+S.11!C7 -> 10 | C11: =5 -> 5 | G11: 10
A12: Proyectos | B12: =Proyectos!C6 -> 60 | C12: =Proyectos!C5 -> 10 | G12: 60
A13: Prácticas | B13: =Practicas!C6 -> 20 | C13: =Practicas!C5 -> 8 | G13: 20
A14: Tareas | B14: =Tareas!C6 -> 10 | C14: =Tareas!C5 -> 14 | G14: 10
A15: Total | B15: =SUM(B11:B14) -> 100 | C15: =SUM(C11:C14) -> 37 | D15: Validacion | E15: =IFERROR(__xludf.DUMMYFUNCTION("LET( nombres,A11:A14, p,B11:B14, m,G11:G14, t,SUM(p), exceden, IFERROR(TEXTJOIN(""; "", TRUE, FILTER(nombres&"" (""&p&"">""&m&"")"", p>m)), """"), negs, IF(COUNTIF(p,""<0"")>0, ""Hay valores negativos"", """"), totalmsg, IF(t<>100, ""Total ≠"&" 100 (actual ""&t&"")"", """"), excesomsg, IF(exceden<>"""", ""Exceden: ""&exceden, """"), msg, TEXTJOIN("" | "", TRUE, totalmsg, negs, excesomsg), IF(msg="""", ""✅ Distribución válida"", ""❌ Revisar: ""&msg) )"),"✅ Distribución válida") -> ✅ Distribución válida

Sheet Competencias
B1: Competencias que se formaran en el Segundo Semestre 2026
B2: Curso | C2: 722 - Teoría de Sistemas 1
B3: Semestre que aplica | C3: Segundo Semestre 2026
B5: Competencias relacionadas al perfil del egresado (Especifica) | I5: Competencias relacionadas al perfil del egresado (General)
B6: 1 | C6: Aplica los conocimientos de su disciplina en la elaboración, fundamentación y defensa de argumentos para prevenir y resolver problemas complejos en su campo profesional, identificando y aplicando innovaciones. | I6: 1 | J6: Aplica principios básicos de ingeniería, ciencias de computación y sistemas de información y comunicación, en la formulación y resolución adecuada de problemas complejos.
B7: 2 | C7: Demuestra pensamiento crítico, actitud investigativa y rigor analítico en el planteamiento y la resolución de problemas complejos. | I7: 2 | J7: Aplica estándares de calidad, eficiencia y seguridad en la implementación adecuada de soluciones de software, hardware y TIC en general.
B8: 3 | C8: Demuestra destreza y habilidad en la selección, uso y adaptación de herramientas metodológicas, tecnológicas, equipos especializados y en la lectura e interpretación de datos, pertinentes al contexto de su ejercicio profesional. | I8: 3
B11: No | C11: Tipo | D11: Verbo en Presente | E11: Objeto de la acción | G11: [Palabras conectoreas] Herramientas o metodología | H11: [Palabras conectoreas] Condiciones específicas | J11: Nivel
B12: 1 | C12: Especifica | D12: Analiza .. | E12: los principios basicos de la teoría de sistemas y su importancia en la vida | G12: mediante modelos sistémicos y recursos gráficos | H12: para analizar el funcionamiento, la estructura y las interacciones de los sistemas en distintos entornos tecnológicos | J12: Analizar
C13: =D12 & " " & E12 & " " &G12& " " &H12& " " -> Analiza .. los principios basicos de la teoría de sistemas y su importancia en la vida mediante modelos sistémicos y recursos gráficos para analizar el funcionamiento, la estructura y las interacciones de los sistemas en distintos entornos tecnológicos
B14: 2 | C14: Especifica | D14: Refina | E14: un problema de ingeniería o un sistema complejo | G14: mediante el uso de Diagramas de Ciclos Causales, Mapas DSRP y metodologías de modelación sistémica | H14: para identificar relaciones causales, retroalimentaciones y estructuras subyacentes que permitan mejorar su comprensión y gestión. | J14: Comprender
C15: =D14 & " " & E14 & " " &G14& " " &H14& " " -> Refina un problema de ingeniería o un sistema complejo mediante el uso de Diagramas de Ciclos Causales, Mapas DSRP y metodologías de modelación sistémica para identificar relaciones causales, retroalimentaciones y estructuras subyacentes que permitan mejorar su comprensión y gestión.
B16: 3 | C16: Especifica | D16: emplea | E16: los principios básicos de la teoría general de sistemas y del enfoque sistémico | G16: el desarrollo de simulaciones dinámicas y la práctica constante de hábitos de pensamiento sistémico | H16: para formular soluciones a problemas de baja y media complejidad | J16: Aplicar
C17: =D16 & " " & E16 & " " &G16& " " &H16& " " -> emplea los principios básicos de la teoría general de sistemas y del enfoque sistémico el desarrollo de simulaciones dinámicas y la práctica constante de hábitos de pensamiento sistémico para formular soluciones a problemas de baja y media complejidad
B18: 4 | C18: Especifica | D18: comprende | E18: los fundamentos conceptuales del pensamiento sistémico y la naturaleza de los sistemas de la realidad | G18: a través del estudio de teorías, modelos mentales y estructuras de retroalimentación | H18: para distinguir los sistemas naturales, físicos diseñados, abstractos diseñados y de actividad humana | J18: Comprender
C19: =D18 & " " & E18 & " " &G18& " " &H18& " " -> comprende los fundamentos conceptuales del pensamiento sistémico y la naturaleza de los sistemas de la realidad a través del estudio de teorías, modelos mentales y estructuras de retroalimentación para distinguir los sistemas naturales, físicos diseñados, abstractos diseñados y de actividad humana
B20: 5 | C20: Especifica | D20: identifica | E20: los conceptos fundamentales de la teoría de sistemas y del pensamiento sistémico | G20: mediante la revisión de definiciones | H20: para reconocer los elementos esenciales en el análisis y modelación de sistemas | J20: Recordar
C21: =D20 & " " & E20 & " " &G20& " " &H20& " " -> identifica los conceptos fundamentales de la teoría de sistemas y del pensamiento sistémico mediante la revisión de definiciones para reconocer los elementos esenciales en el análisis y modelación de sistemas
B22: 6 | C22: Especifica | D22: Diseña | E22: un controlador (ej. PID) o una estrategia de intervención sistémica | G22: para articular las herramientas de modelado y simulación | H22: para combinar las herramientas de modelado y simulación | J22: Crear
C23: =D22 & " " & E22 & " " &G22& " " &H22& " " -> Diseña un controlador (ej. PID) o una estrategia de intervención sistémica para articular las herramientas de modelado y simulación para combinar las herramientas de modelado y simulación
B24: 7 | C24: Especifica | D24: desarrolla | E24: pensamiento sistémico y la construcción de modelos mentales sistémicos | G24: con el fin de comprender, representar | H24: para comprender sistemas complejos en entornos dinámicos y multidisciplinarios | J24: Crear
C25: =D24 & " " & E24 & " " &G24& " " &H24& " " -> desarrolla pensamiento sistémico y la construcción de modelos mentales sistémicos con el fin de comprender, representar para comprender sistemas complejos en entornos dinámicos y multidisciplinarios
B28: Si las competencias son las misma que el semetre anterior compartenos tu opinion de porque no se cambiaron

Sheet Diseño
B2: Diseño de Contenido Curricular
B4: Curso | C4: 722 - Teoría de Sistemas 1
B5: semestre que aplica | C5: Segundo Semestre 2026
B8: No. | C8: Competencia | D8: Nombre de la Unidad | E8: Tema | F8: Subtema | G8: Mes | H8: Semana
B9: 1 | C9: identifica los conceptos fundamentales de la teoría de sistemas y del pensamiento sistémico mediante la revisión de definiciones para reconocer los elementos esenciales en el análisis y modelación de sistemas | D9: Unidad 1: Introducción al pensamiento sistémico | E9: Los modelos mentales o sistemas abstractos diseñados | F9: Pensar en sistemas o pensar de otras maneras | G9: JULIO | H9: 2
B10: 2 | C10: identifica los conceptos fundamentales de la teoría de sistemas y del pensamiento sistémico mediante la revisión de definiciones para reconocer los elementos esenciales en el análisis y modelación de sistemas | D10: Unidad 1: Introducción al pensamiento sistémico | E10: Los modelos mentales o sistemas abstractos diseñados | F10: La realidad interpretada por el pensamiento | G10: JULIO | H10: 2
B11: 3 | C11: identifica los conceptos fundamentales de la teoría de sistemas y del pensamiento sistémico mediante la revisión de definiciones para reconocer los elementos esenciales en el análisis y modelación de sistemas | D11: Unidad 1: Introducción al pensamiento sistémico | E11: Los modelos mentales o sistemas abstractos diseñados | F11: La dinámica de los modelos mentales | G11: JULIO | H11: 2
B12: 4 | C12: identifica los conceptos fundamentales de la teoría de sistemas y del pensamiento sistémico mediante la revisión de definiciones para reconocer los elementos esenciales en el análisis y modelación de sistemas | D12: Unidad 1: Introducción al pensamiento sistémico | E12: Los modelos mentales o sistemas abstractos diseñados | F12: La escalera de inferencias | G12: JULIO | H12: 2
B13: 5 | C13: identifica los conceptos fundamentales de la teoría de sistemas y del pensamiento sistémico mediante la revisión de definiciones para reconocer los elementos esenciales en el análisis y modelación de sistemas | D13: Unidad 1: Introducción al pensamiento sistémico | E13: Los modelos mentales o sistemas abstractos diseñados | F13: Modelos mentales sistémicos | G13: JULIO | H13: 2
B14: 6 | C14: identifica los conceptos fundamentales de la teoría de sistemas y del pensamiento sistémico mediante la revisión de definiciones para reconocer los elementos esenciales en el análisis y modelación de sistemas | D14: Unidad 1: Introducción al pensamiento sistémico | E14: Los modelos mentales o sistemas abstractos diseñados | F14: Comparación de sistemas abstractos | G14: JULIO | H14: 2
B15: 7 | C15: identifica los conceptos fundamentales de la teoría de sistemas y del pensamiento sistémico mediante la revisión de definiciones para reconocer los elementos esenciales en el análisis y modelación de sistemas | D15: Unidad 1: Introducción al pensamiento sistémico | E15: Los modelos mentales o sistemas abstractos diseñados | F15: Operaciones mentales básicas | G15: JULIO | H15: 2
B16: 8 | C16: identifica los conceptos fundamentales de la teoría de sistemas y del pensamiento sistémico mediante la revisión de definiciones para reconocer los elementos esenciales en el análisis y modelación de sistemas | D16: Unidad 2: Los sistemas abstractos diseñados | E16: Operaciones mentales sistémicas | F16: Operaciones mentales básicas del pensamiento sistémico | G16: JULIO | H16: 2
B17: 9 | C17: identifica los conceptos fundamentales de la teoría de sistemas y del pensamiento sistémico mediante la revisión de definiciones para reconocer los elementos esenciales en el análisis y modelación de sistemas | D17: Unidad 2: Los sistemas abstractos diseñados | E17: Operaciones mentales sistémicas | F17: El pensamiento sistémico como emergente | G17: JULIO | H17: 2
B18: 10 | C18: identifica los conceptos fundamentales de la teoría de sistemas y del pensamiento sistémico mediante la revisión de definiciones para reconocer los elementos esenciales en el análisis y modelación de sistemas | D18: Unidad 2: Los sistemas abstractos diseñados | E18: Operaciones mentales sistémicas | F18: Hábitos relacionados con los sistemas abstractos | G18: JULIO | H18: 3
B19: 11 | C19: identifica los conceptos fundamentales de la teoría de sistemas y del pensamiento sistémico mediante la revisión de definiciones para reconocer los elementos esenciales en el análisis y modelación de sistemas | D19: Unidad 2: Los sistemas abstractos diseñados | E19: Operaciones mentales sistémicas | F19: El pensamiento adaptativo complejo | G19: JULIO | H19: 3
B20: 12 | C20: identifica los conceptos fundamentales de la teoría de sistemas y del pensamiento sistémico mediante la revisión de definiciones para reconocer los elementos esenciales en el análisis y modelación de sistemas | D20: Unidad 2: Los sistemas abstractos diseñados | E20: Operaciones mentales sistémicas | F20: La perspectiva en sistemas abstractos | G20: JULIO | H20: 3
... B97: 89 | C97: emplea los principios básicos de la teoría general de sistemas y del enfoque sistémico el desarrollo de simulaciones dinámicas y la práctica constante de hábitos de pensamiento sistémico para formular soluciones a problemas de baja y media complejidad | D97: Unidad 5: Toma de decisiones sistémicas | E97: Toma de decisiones sistémicas | F97: Impacto de la retroalimentación en decisiones | G97: OCTUBRE | H97: 11
B98: 90
B99: 91
B100: 92
B101: 93
B102: 94
B103: 95
B104: 96
B105: 97
B106: 98
B107: 99
B108: 100

Sheet Semana Diagnostico
B2: Diseño de Contenido Curricular
B4: Curso | C4: ='Diseño'!C4 -> 722 - Teoría de Sistemas 1
B5: Semana | C5: 1
B6: Tiempo | C6: =B15+B22+B29+B41+B47+B36 -> 100
K8: Estos puntos son recomendaciones de los puntos a tratar durante tu presentacion, si no usaras estos eres libre de agregar mas filas para indicar que haras. En los recuadros de la derecha colocar breve resumen de lo que planeas decir. No debes ser muy especifico seran pequeñas anotaciones que te ayudaran a recordar lo que planeaste
A9: 1. Bienvenida y Presentación | G9: Tiempo Aproximado | H9: =B15 -> 10
G10: No puedes excederte mas de 15 minutos
A11: Nombre y Formacion Academica | B11: Presentar mi nombre, edad, breve explicacion de mi carrera de sistemas actualmente en el noveno semestre
A12: Experiencia docente y profecional | B12: contar experiencia laboral como desarollador backend
A13: Rol del auxiliar dentro del curso (funciones, actividades y apoyo a los estudiantes). | B13: Indicar apoyo al estudiante por medio de los foros de classroom
A14: Expectativas sobre la dinámica del curso | B14: Participación activa, Pensamiento Crítico y enfoque en apoyo al estudiante
A15: Tiempo que emplearas | B15: 10
A18: 2. Evaluación de Conocimientos Previos | G18: Tiempo Aproximado | H18: =B22 -> 30
G19: No puedes excederte mas de 45 minutos | K19: En los recuadors de la derecha deberas colocar las preguntas que planeas realizar con sus respectivas respuestas. En el segundo recuadro deberas colocar un breve resumne de lo que tines planificado para la parte practica del curso previo al que estas impartiendo.
A20: Redactaras de 15 a 20 preguntas con sus respectivas respuestas , por lo que debes escoge los temas que evaluaras | B20: conceptos basicos sobre teoria de sistemas y pensamiento sistémico
A21: Redactaras una parte practica para realizar la evaluacion de conocimientos previos | B21: Pedir a los estudiantes (ejercicio rápido en el chat/pizarra) que tomen un proceso simple de la vida real (ej. ir al banco, hacer café) y que: 1. Diseñen un Diagrama de Flujo simple que muestre la secuencia de pasos, decisiones y terminación. 2. Identifiquen 3 variables que cambiarían el resultado del proceso (ej. falta de insumos, estado de ánimo).
A22: Tiempo que emplearas | B22: 30
A25: 3. Presentación de los Estudiantes | G25: Tiempo Aproximado | H25: =B29 -> 30
G26: No puedes excederte mas de 30 minutos
A27: Seleccion al Azar de 5 Estudiantes | B27: Utilizaré un generador de números al azar basado en el número de lista de asistencia (ej. un spinner wheel online). | K27: En el primer recuadro colocaras la metodollogia que adoptaras para la eleccion de los estudiantes. En el segundo recuadro colocaras la redaccion de las preguntas que comprendan los siguientes puntos respecto al estudiante: Nombre. Intereses y expectativas sobre el curso. Experiencia previa relacionada con el curso (si aplica). Un dato curioso sobre sí mismo. Consideras que la prueba de conociminetos previos esta acorde al conocimiento que se te brindo en su momento Que tan comodo se sintio con la prueba anterior.
A28: Indica las preguntas que responderan los estudiantes afortunados | B28: 1. Dime tu nombre completo y tu área de interés principal en ingeniería. 2. ¿Qué es lo que más te emociona/esperas aprender en este curso (Pensamiento Sistémico, Modelos Mentales, VENSIM, etc.)? 3. ¿Tienes experiencia previa relacionada con análisis de sistemas o modelado (aunque sea conceptual)?
A29: Tiempo que emplearas | B29: 30
A32: 4. Senso de Horarios de Calificación | G32: Tiempo Aproximado | H32: =B36 -> 10
A33: Deberas estar recordando que deben contestar el formulario asi mismo dejar el link fijado en la llamada | G33: Esta actividad quedara abierta hasta el fin de la clase. pero emplearas 5 min especificos para la actividad
A34: Link de google forms donde este el cuestionario | K34: Esta actividad te ayudara a realizar un senso de posibles horarios de calificacion y que tus estudiantes esten enterados y puedan preveer los dias de calificacion y asi mismo el horario. Deberas colocar en los reacuadros de la derecha link de Google form libre para correos intitucionales, esto para garantizar una sola respuesta por estudiante. TAmbien deberas colocar los posibles horarios y dias que tentativamente tendrias disponibles. para colocarlos en el google form.
A35: Dias y posibles Horarios de calificacion | B35: Sabados a partir de 10 AM
A36: Tiempo que emplearas | B36: 10
A39: 5. Mostrar Programa del Curso | G39: Tiempo Aproximado | H39: =B41 -> 10
G40: No puedes excederte mas de 30 minutos
A41: Tiempo que emplearas | B41: 10
A44: 6. Evaluación de Conocimientos del Curso Actual | G44: Tiempo Aproximado | H44: =B47 -> 10
G45: No puedes excederte mas de 15 minutos
A46: Redactaras 20 preguntas con sus respectivas respuestas | B46: Preguntas y Respuestas (20 preguntas, 15 min): (Ejemplos que miden interés y expectativa sobre el contenido que acabas de presentar y que verán) 1. ¿Qué es la Escalera de Inferencias? (R: Proceso mental que lleva de datos a creencias/acciones). 2. Mencione una Operación Mental Sistémica. (R: Distinción, Relación, Perspectiva, Organización). 3. ¿Cuál es el objetivo principal del Modelo del Iceberg? (R: Buscar causas estructurales, no solo eventos). 4. ¿Qué representan las flechas en un Diagrama de Ciclos Causales (DCC)? (R: Relaciones de causalidad). 5. Defina Retroalimentación de Refuerzo (R). (R: Mecanismo que amplifica el cambio o causa crecimiento/declive exponencial). 6. Mencione el software que usaremos para simulación dinámica. (R: VENSIM). 7. ¿Qué es un Arquetipo Sistémico? (R: Estructura de DCC recurrente que causa problemas comunes). 8. ¿Cuál es la diferencia entre un Bucle R y uno C en la dinámica? (R: R genera crecimiento/declive; C genera equilibrio/estabilidad). 9. ¿Qué significa Alto Apalancamiento en intervención? (R: Un pequeño cambio estructural que genera gran impacto en el sistema). 10. ¿En qué unidad se enfoca el curso en la Toma de Decisiones Estratégicas? (R: Unidad 5).
A47: Tiempo que emplearas | B47: 10

Sheet S.2
B2: Diseño de la Sesión de Laboratorio
B4: Curso | C4: ='Diseño'!C4 -> 722 - Teoría de Sistemas 1
B5: Semana | C5: 2
B6: Tiempo | C6: =H10+H21+H44+H68 -> 100
B7: Ponderación | C7: =B49+B60 -> 1
B8: Validación de Tiempo | C8: =IF(H44<=0, "❌ ERROR: La Actividad 1 debe tener un tiempo mayor a 0.", IF(H21>60, "❌ ERROR: El 'Área de Conocimiento' no puede exceder los 60 min.", IF((H10+H21+H44)<100, "❌ ERROR: El tiempo total debe ser de al menos 100 min.", "✅ VALIDACIÓN CORRECTA"))) -> ❌ ERROR: El tiempo total debe ser de al menos 100 min.
A10: 1. Área Actitudinal (Saber Ser) | G10: Tiempo Aproximado | H10: =B13 -> 5
G11: Tiene que estar en un rango de 3 a 5 minutos
A12: Nombre del Valor | B12: Apertura mental
A13: Tiempo Aproximado | B13: 5
A14: Descripcion
A15: Disposición a cuestionar las propias suposiciones y reconocer que la "realidad" es subjetivamente interpretada por filtros mentales.
A17: Como se relaciona con los conocimientos de la sesion y se aplicaria
A18: La sesión se centra en la Escalera de Inferencias. Aplicar la Apertura Mental permite al estudiante identificar sus propios juicios y sesgos, mejorando la calidad de su análisis antes de formular modelos.
A21: 2. Área Conocimiento (Saber) | G21: Tiempo Aproximado | H21: =SUM(D39:H42) -> 45
G22: No puede exceder los 60 minutos
A23: Competencia a desarrollar | B23: identifica los conceptos fundamentales de la teoría de sistemas y del pensamiento sistémico mediante la revisión de definiciones para reconocer los elementos esenciales en el análisis y modelación de sistemas
A24: Competencia a desarrollar
A26: 2.1 Contenido
A27: No. | B27: Unidad | D27: Tema | F27: Sub Tema
A28: 1 | B28: =IFERROR(__xludf.DUMMYFUNCTION("FILTER('Diseño'!D:D,'Diseño'!H:H=$C$5)"),"Unidad 1: Introducción al pensamiento sistémico") -> Unidad 1: Introducción al pensamiento sistémico | D28: =IFERROR(__xludf.DUMMYFUNCTION("FILTER('Diseño'!E:E,'Diseño'!H:H=$C$5)"),"Los modelos mentales o sistemas abstractos diseñados") -> Los modelos mentales o sistemas abstractos diseñados | F28: =IFERROR(__xludf.DUMMYFUNCTION("FILTER('Diseño'!F:F,'Diseño'!H:H=$C$5)"),"Pensar en sistemas o pensar de otras maneras") -> Pensar en sistemas o pensar de otras maneras
A29: 2 | B29: =IFERROR(__xludf.DUMMYFUNCTION("""COMPUTED_VALUE"""),"Unidad 1: Introducción al pensamiento sistémico") -> Unidad 1: Introducción al pensamiento sistémico | D29: =IFERROR(__xludf.DUMMYFUNCTION("""COMPUTED_VALUE"""),"Los modelos mentales o sistemas abstractos diseñados") -> Los modelos mentales o sistemas abstractos diseñados | F29: =IFERROR(__xludf.DUMMYFUNCTION("""COMPUTED_VALUE"""),"La realidad interpretada por el pensamiento") -> La realidad interpretada por el pensamiento
A30: 3 | B30: =IFERROR(__xludf.DUMMYFUNCTION("""COMPUTED_VALUE"""),"Unidad 1: Introducción al pensamiento sistémico") -> Unidad 1: Introducción al pensamiento sistémico | D30: =IFERROR(__xludf.DUMMYFUNCTION("""COMPUTED_VALUE"""),"Los modelos mentales o sistemas abstractos diseñados") -> Los modelos mentales o sistemas abstractos diseñados | F30: =IFERROR(__xludf.DUMMYFUNCTION("""COMPUTED_VALUE"""),"La dinámica de los modelos mentales") -> La dinámica de los modelos mentales
A31: 4 | B31: =IFERROR(__xludf.DUMMYFUNCTION("""COMPUTED_VALUE"""),"Unidad 1: Introducción al pensamiento sistémico") -> Unidad 1: Introducción al pensamiento sistémico | D31: =IFERROR(__xludf.DUMMYFUNCTION("""COMPUTED_VALUE"""),"Los modelos mentales o sistemas abstractos diseñados") -> Los modelos mentales o sistemas abstractos diseñados | F31: =IFERROR(__xludf.DUMMYFUNCTION("""COMPUTED_VALUE"""),"La escalera de inferencias") -> La escalera de inferencias
A32: 5 | B32: =IFERROR(__xludf.DUMMYFUNCTION("""COMPUTED_VALUE"""),"Unidad 1: Introducción al pensamiento sistémico") -> Unidad 1: Introducción al pensamiento sistémico | D32: =IFERROR(__xludf.DUMMYFUNCTION("""COMPUTED_VALUE"""),"Los modelos mentales o sistemas abstractos diseñados") -> Los modelos mentales o sistemas abstractos diseñados | F32: =IFERROR(__xludf.DUMMYFUNCTION("""COMPUTED_VALUE"""),"Modelos mentales sistémicos") -> Modelos mentales sistémicos
A33: 6 | B33: =IFERROR(__xludf.DUMMYFUNCTION("""COMPUTED_VALUE"""),"Unidad 1: Introducción al pensamiento sistémico") -> Unidad 1: Introducción al pensamiento sistémico | D33: =IFERROR(__xludf.DUMMYFUNCTION("""COMPUTED_VALUE"""),"Los modelos mentales o sistemas abstractos diseñados") -> Los modelos mentales o sistemas abstractos diseñados | F33: =IFERROR(__xludf.DUMMYFUNCTION("""COMPUTED_VALUE"""),"Comparación de sistemas abstractos") -> Comparación de sistemas abstractos
A34: 7 | B34: =IFERROR(__xludf.DUMMYFUNCTION("""COMPUTED_VALUE"""),"Unidad 1: Introducción al pensamiento sistémico") -> Unidad 1: Introducción al pensamiento sistémico | D34: =IFERROR(__xludf.DUMMYFUNCTION("""COMPUTED_VALUE"""),"Los modelos mentales o sistemas abstractos diseñados") -> Los modelos mentales o sistemas abstractos diseñados | F34: =IFERROR(__xludf.DUMMYFUNCTION("""COMPUTED_VALUE"""),"Operaciones mentales básicas") -> Operaciones mentales básicas
B35: =IFERROR(__xludf.DUMMYFUNCTION("""COMPUTED_VALUE"""),"Unidad 2: Los sistemas abstractos diseñados") -> Unidad 2: Los sistemas abstractos diseñados | D35: =IFERROR(__xludf.DUMMYFUNCTION("""COMPUTED_VALUE"""),"Operaciones mentales sistémicas") -> Operaciones mentales sistémicas | F35: =IFERROR(__xludf.DUMMYFUNCTION("""COMPUTED_VALUE"""),"Operaciones mentales básicas del pensamiento sistémico") -> Operaciones mentales básicas del pensamiento sistémico
A36: 2.2 Recursos Educativos | B36: =IFERROR(__xludf.DUMMYFUNCTION("""COMPUTED_VALUE"""),"Unidad 2: Los sistemas abstractos diseñados") -> Unidad 2: Los sistemas abstractos diseñados | D36: =IFERROR(__xludf.DUMMYFUNCTION("""COMPUTED_VALUE"""),"Operaciones mentales sistémicas") -> Operaciones mentales sistémicas | F36: =IFERROR(__xludf.DUMMYFUNCTION("""COMPUTED_VALUE"""),"El pensamiento sistémico como emergente") -> El pensamiento sistémico como emergente
A38: Tipo de Recurso a utilizar | B38: Tipo | C38: Valor maximo recomendado en Minutos | D38: Tiempo Aproximado ( unicamente el valor de minutos ) | I38: Validacion
A39: Presentacion | B39: Obligatorio | C39: 30 | D39: 25 | I39: =IF(D39<=C39,"Correcto", "Corregir") -> Correcto
A40: Video | B40: Obligatorio | C40: 6 | D40: 5 | I40: =IF(D40<=C40,"Correcto", "Corregir") -> Correcto
A41: Lectura | B41: Optativo | C41: 10 | D41: 5 | I41: =IF(D41<=C41,"Correcto", "Corregir") -> Correcto
A42: Ejercicio Demostrativo | B42: Obligatorio | C42: 30 | D42: 10 | I42: =IF(D42<=C42,"Correcto", "Corregir") -> Correcto
A44: 3. Área de Habilidades (Saber Hacer) | G44: Tiempo Aproximado | H44: =B50 -> 40
G45: Tiene que estar en un rango de 30 a 50 minutos
A46: Actividad 1 (Obligatoria)
A47: Competencia que predomina en la actividad | B47: Refina un problema de ingeniería o un sistema complejo mediante el uso de Diagramas de Ciclos Causales, Mapas DSRP y metodologías de modelación sistémica para identificar relaciones causales, retroalimentaciones y estructuras subyacentes que permitan mejorar su comprensión y gestión.
A48: Tipo de Actividad | B48: Analisis
A49: Ponderación | B49: 1
...

Sheet S.3
B2: Diseño de la Sesión de Laboratorio
B4: Curso | C4: ='Diseño'!C4 -> 722 - Teoría de Sistemas 1
B5: Semana | C5: 3
B6: Tiempo | C6: =H10+H21+H44+H68 -> 100
B7: Ponderación | C7: =B49+B60 -> 1
B8: Validación de Tiempo | C8: =IF(H44<=0, "❌ ERROR: La Actividad 1 debe tener un tiempo mayor a 0.", IF(H21>60, "❌ ERROR: El 'Área de Conocimiento' no puede exceder los 60 min.", IF((H10+H21+H44)<100, "❌ ERROR: El tiempo total debe ser de al menos 100 min.", "✅ VALIDACIÓN CORRECTA"))) -> ❌ ERROR: El tiempo total debe ser de al menos 100 min.
A10: 1. Área Actitudinal (Saber Ser) | G10: Tiempo Aproximado | H10: =B13 -> 5
G11: Tiene que estar en un rango de 3 a 5 minutos
A12: Nombre del Valor | B12: Conciencia Sistémica
A13: Tiempo Aproximado | B13: 5
A14: Descripcion
A15: Reconocer que las soluciones eficaces se encuentran en el cambio de estructura y perspectiva (el sistema), no solo de los componentes.
A17: Como se relaciona con los conocimientos de la sesion y se aplicaria
A18: Se relaciona con el Pensamiento Sistémico como Emergente y la Perspectiva. Fomenta la habilidad de Comprender que los problemas complejos requieren cambiar el marco mental (paradigma), un paso esencial antes de aplicar soluciones técnicas.
A21: 2. Área Conocimiento (Saber) | G21: Tiempo Aproximado | H21: =SUM(D39:H42) -> 50
G22: No puede exceder los 60 minutos
A23: Competencia a desarrollar | B23: comprende los fundamentos conceptuales del pensamiento sistémico y la naturaleza de los sistemas de la realidad a través del estudio de teorías, modelos mentales y estructuras de retroalimentación para distinguir los sistemas naturales, físicos diseñados, abstractos diseñados y de actividad humana
A24: Competencia a desarrollar
A26: 2.1 Contenido
A27: No. | B27: Unidad | D27: Tema | F27: Sub Tema
A28: 1 | B28: =IFERROR(__xludf.DUMMYFUNCTION("FILTER('Diseño'!D:D,'Diseño'!H:H=$C$5)"),"Unidad 2: Los sistemas abstractos diseñados") -> Unidad 2: Los sistemas abstractos diseñados | D28: =IFERROR(__xludf.DUMMYFUNCTION("FILTER('Diseño'!E:E,'Diseño'!H:H=$C$5)"),"Operaciones mentales sistémicas") -> Operaciones mentales sistémicas | F28: =IFERROR(__xludf.DUMMYFUNCTION("FILTER('Diseño'!F:F,'Diseño'!H:H=$C$5)"),"Hábitos relacionados con los sistemas abstractos") -> Hábitos relacionados con los sistemas abstractos
A29: 2 | B29: =IFERROR(__xludf.DUMMYFUNCTION("""COMPUTED_VALUE"""),"Unidad 2: Los sistemas abstractos diseñados") -> Unidad 2: Los sistemas abstractos diseñados | D29: =IFERROR(__xludf.DUMMYFUNCTION("""COMPUTED_VALUE"""),"Operaciones mentales sistémicas") -> Operaciones mentales sistémicas | F29: =IFERROR(__xludf.DUMMYFUNCTION("""COMPUTED_VALUE"""),"El pensamiento adaptativo complejo") -> El pensamiento adaptativo complejo
A30: 3 | B30: =IFERROR(__xludf.DUMMYFUNCTION("""COMPUTED_VALUE"""),"Unidad 2: Los sistemas abstractos diseñados") -> Unidad 2: Los sistemas abstractos diseñados | D30: =IFERROR(__xludf.DUMMYFUNCTION("""COMPUTED_VALUE"""),"Operaciones mentales sistémicas") -> Operaciones mentales sistémicas | F30: =IFERROR(__xludf.DUMMYFUNCTION("""COMPUTED_VALUE"""),"La perspectiva en sistemas abstractos") -> La perspectiva en sistemas abstractos
A31: 4 | B31: =IFERROR(__xludf.DUMMYFUNCTION("""COMPUTED_VALUE"""),"Unidad 2: Los sistemas abstractos diseñados") -> Unidad 2: Los sistemas abstractos diseñados | D31: =IFERROR(__xludf.DUMMYFUNCTION("""COMPUTED_VALUE"""),"Operaciones mentales sistémicas") -> Operaciones mentales sistémicas | F31: =IFERROR(__xludf.DUMMYFUNCTION("""COMPUTED_VALUE"""),"Comparación entre sistemas diseñados") -> Comparación entre sistemas diseñados
A32: 5 | B32: =IFERROR(__xludf.DUMMYFUNCTION("""COMPUTED_VALUE"""),"Unidad 2: Los sistemas abstractos diseñados") -> Unidad 2: Los sistemas abstractos diseñados | D32: =IFERROR(__xludf.DUMMYFUNCTION("""COMPUTED_VALUE"""),"Operaciones mentales sistémicas") -> Operaciones mentales sistémicas | F32: =IFERROR(__xludf.DUMMYFUNCTION("""COMPUTED_VALUE"""),"Ejemplos de sistemas mentales") -> Ejemplos de sistemas mentales
A33: 6 | B33: =IFERROR(__xludf.DUMMYFUNCTION("""COMPUTED_VALUE"""),"Unidad 2: Los sistemas abstractos diseñados") -> Unidad 2: Los sistemas abstractos diseñados | D33: =IFERROR(__xludf.DUMMYFUNCTION("""COMPUTED_VALUE"""),"Compartir modelos mentales") -> Compartir modelos mentales | F33: =IFERROR(__xludf.DUMMYFUNCTION("""COMPUTED_VALUE"""),"Sistemas abstractos diseñados compartidos (paradigmas)") -> Sistemas abstractos diseñados compartidos (paradigmas)
A34: 7 | B34: =IFERROR(__xludf.DUMMYFUNCTION("""COMPUTED_VALUE"""),"Unidad 2: Los sistemas abstractos diseñados") -> Unidad 2: Los sistemas abstractos diseñados | D34: =IFERROR(__xludf.DUMMYFUNCTION("""COMPUTED_VALUE"""),"Compartir modelos mentales") -> Compartir modelos mentales | F34: =IFERROR(__xludf.DUMMYFUNCTION("""COMPUTED_VALUE"""),"Paradigmas en contextos específicos") -> Paradigmas en contextos específicos
B35: =IFERROR(__xludf.DUMMYFUNCTION("""COMPUTED_VALUE"""),"Unidad 2: Los sistemas abstractos diseñados") -> Unidad 2: Los sistemas abstractos diseñados | D35: =IFERROR(__xludf.DUMMYFUNCTION("""COMPUTED_VALUE"""),"Compartir modelos mentales") -> Compartir modelos mentales | F35: =IFERROR(__xludf.DUMMYFUNCTION("""COMPUTED_VALUE"""),"Comparación con otros paradigmas") -> Comparación con otros paradigmas
A36: 2.2 Recursos Educativos | B36: =IFERROR(__xludf.DUMMYFUNCTION("""COMPUTED_VALUE"""),"Unidad 2: Los sistemas abstractos diseñados") -> Unidad 2: Los sistemas abstractos diseñados | D36: =IFERROR(__xludf.DUMMYFUNCTION("""COMPUTED_VALUE"""),"Compartir modelos mentales") -> Compartir modelos mentales | F36: =IFERROR(__xludf.DUMMYFUNCTION("""COMPUTED_VALUE"""),"Ejemplos de paradigmas compartidos") -> Ejemplos de paradigmas compartidos
A38: Tipo de Recurso a utilizar | B38: Tipo | C38: Valor maximo recomendado en Minutos | D38: Tiempo Aproximado ( unicamente el valor de minutos ) | I38: Validacion
A39: Presentacion | B39: Obligatorio | C39: 30 | D39: 20 | I39: =IF(D39<=C39,"Correcto", "Corregir") -> Correcto
A40: Video | B40: Obligatorio | C40: 6 | D40: 5 | I40: =IF(D40<=C40,"Correcto", "Corregir") -> Correcto
A41: Lectura | B41: Optativo | C41: 10 | D41: 5 | I41: =IF(D41<=C41,"Correcto", "Corregir") -> Correcto
A42: Ejercicio Demostrativo | B42: Obligatorio | C42: 30 | D42: 20 | I42: =IF(D42<=C42,"Correcto", "Corregir") -> Correcto
A44: 3. Área de Habilidades (Saber Hacer) | G44: Tiempo Aproximado | H44: =B50 -> 35
G45: Tiene que estar en un rango de 30 a 50 minutos
A46: Actividad 1 (Obligatoria)
A47: Competencia que predomina en la actividad | B47: comprende los fundamentos conceptuales del pensamiento sistémico y la naturaleza de los sistemas de la realidad a través del estudio de teorías, modelos mentales y estructuras de retroalimentación para distinguir los sistemas naturales, físicos diseñados, abstractos diseñados y de actividad humana
A48: Tipo de Actividad | B48: otros
A49: Ponderación | B49: 1
...

Sheet S.4
B2: Diseño de la Sesión de Laboratorio
B4: Curso | C4: ='Diseño'!C4 -> 722 - Teoría de Sistemas 1
B5: Semana | C5: 4
B6: Tiempo | C6: =H10+H21+H44+H68 -> 100
B7: Ponderación | C7: =B49+B60 -> 1
B8: Validación de Tiempo | C8: =IF(H44<=0, "❌ ERROR: La Actividad 1 debe tener un tiempo mayor a 0.", IF(H21>60, "❌ ERROR: El 'Área de Conocimiento' no puede exceder los 60 min.", IF((H10+H21+H44)<100, "❌ ERROR: El tiempo total debe ser de al menos 100 min.", "✅ VALIDACIÓN CORRECTA"))) -> ❌ ERROR: El tiempo total debe ser de al menos 100 min.
A10: 1. Área Actitudinal (Saber Ser) | G10: Tiempo Aproximado | H10: =B13 -> 5
G11: Tiene que estar en un rango de 3 a 5 minutos
A12: Nombre del Valor | B12: Orientación a la Causa Raíz
A13: Tiempo Aproximado | B13: 5
A14: Descripcion
A15: Enfocarse en la estructura del sistema (el círculo) en lugar de los eventos (la línea) para evitar la transferencia del problema.
A17: Como se relaciona con los conocimientos de la sesion y se aplicaria
A18: Se relaciona con los Ejemplos de Retroalimentación y Pensamiento Circular. Fomenta la habilidad de Comprender y aplicar la lógica sistémica, alejándose de la búsqueda de una única "causa" lineal.
A21: 2. Área Conocimiento (Saber) | G21: Tiempo Aproximado | H21: =SUM(D39:H42) -> 40
G22: No puede exceder los 60 minutos
A23: Competencia a desarrollar | B23: comprende los fundamentos conceptuales del pensamiento sistémico y la naturaleza de los sistemas de la realidad a través del estudio de teorías, modelos mentales y estructuras de retroalimentación para distinguir los sistemas naturales, físicos diseñados, abstractos diseñados y de actividad humana
A24: Competencia a desarrollar
A26: 2.1 Contenido
A27: No. | B27: Unidad | D27: Tema | F27: Sub Tema
A28: 1 | B28: =IFERROR(__xludf.DUMMYFUNCTION("FILTER('Diseño'!D:D,'Diseño'!H:H=$C$5)"),"Unidad 2: Los sistemas abstractos diseñados") -> Unidad 2: Los sistemas abstractos diseñados | D28: =IFERROR(__xludf.DUMMYFUNCTION("FILTER('Diseño'!E:E,'Diseño'!H:H=$C$5)"),"Compartir modelos mentales") -> Compartir modelos mentales | F28: =IFERROR(__xludf.DUMMYFUNCTION("FILTER('Diseño'!F:F,'Diseño'!H:H=$C$5)"),"Impacto en toma de decisiones") -> Impacto en toma de decisiones
A29: 2 | B29: =IFERROR(__xludf.DUMMYFUNCTION("""COMPUTED_VALUE"""),"Unidad 2: Los sistemas abstractos diseñados") -> Unidad 2: Los sistemas abstractos diseñados | D29: =IFERROR(__xludf.DUMMYFUNCTION("""COMPUTED_VALUE"""),"Compartir modelos mentales") -> Compartir modelos mentales | F29: =IFERROR(__xludf.DUMMYFUNCTION("""COMPUTED_VALUE"""),"Evolución de paradigmas") -> Evolución de paradigmas
A30: 3 | B30: =IFERROR(__xludf.DUMMYFUNCTION("""COMPUTED_VALUE"""),"Unidad 2: Los sistemas abstractos diseñados") -> Unidad 2: Los sistemas abstractos diseñados | D30: =IFERROR(__xludf.DUMMYFUNCTION("""COMPUTED_VALUE"""),"Compartir modelos mentales") -> Compartir modelos mentales | F30: =IFERROR(__xludf.DUMMYFUNCTION("""COMPUTED_VALUE"""),"Cambios en modelos mentales compartidos") -> Cambios en modelos mentales compartidos
A31: 4 | B31: =IFERROR(__xludf.DUMMYFUNCTION("""COMPUTED_VALUE"""),"Unidad 2: Los sistemas abstractos diseñados") -> Unidad 2: Los sistemas abstractos diseñados | D31: =IFERROR(__xludf.DUMMYFUNCTION("""COMPUTED_VALUE"""),"Perspectiva de sistemas abstractos diseñados") -> Perspectiva de sistemas abstractos diseñados | F31: =IFERROR(__xludf.DUMMYFUNCTION("""COMPUTED_VALUE"""),"Las perspectivas y los sistemas abstractos") -> Las perspectivas y los sistemas abstractos
A32: 5 | B32: =IFERROR(__xludf.DUMMYFUNCTION("""COMPUTED_VALUE"""),"Unidad 2: Los sistemas abstractos diseñados") -> Unidad 2: Los sistemas abstractos diseñados | D32: =IFERROR(__xludf.DUMMYFUNCTION("""COMPUTED_VALUE"""),"Perspectiva de sistemas abstractos diseñados") -> Perspectiva de sistemas abstractos diseñados | F32: =IFERROR(__xludf.DUMMYFUNCTION("""COMPUTED_VALUE"""),"Impacto de las perspectivas en decisiones") -> Impacto de las perspectivas en decisiones
A33: 6 | B33: =IFERROR(__xludf.DUMMYFUNCTION("""COMPUTED_VALUE"""),"Unidad 2: Los sistemas abstractos diseñados") -> Unidad 2: Los sistemas abstractos diseñados | D33: =IFERROR(__xludf.DUMMYFUNCTION("""COMPUTED_VALUE"""),"Perspectiva de sistemas abstractos diseñados") -> Perspectiva de sistemas abstractos diseñados | F33: =IFERROR(__xludf.DUMMYFUNCTION("""COMPUTED_VALUE"""),"Operaciones mentales avanzadas en pensamiento sistémico") -> Operaciones mentales avanzadas en pensamiento sistémico
A34: 7 | B34: =IFERROR(__xludf.DUMMYFUNCTION("""COMPUTED_VALUE"""),"Unidad 2: Los sistemas abstractos diseñados") -> Unidad 2: Los sistemas abstractos diseñados | D34: =IFERROR(__xludf.DUMMYFUNCTION("""COMPUTED_VALUE"""),"Perspectiva de sistemas abstractos diseñados") -> Perspectiva de sistemas abstractos diseñados | F34: =IFERROR(__xludf.DUMMYFUNCTION("""COMPUTED_VALUE"""),"Interrelaciones entre modelos mentales") -> Interrelaciones entre modelos mentales
B35: =IFERROR(__xludf.DUMMYFUNCTION("""COMPUTED_VALUE"""),"Unidad 2: Los sistemas abstractos diseñados") -> Unidad 2: Los sistemas abstractos diseñados | D35: =IFERROR(__xludf.DUMMYFUNCTION("""COMPUTED_VALUE"""),"Perspectiva de sistemas abstractos diseñados") -> Perspectiva de sistemas abstractos diseñados | F35: =IFERROR(__xludf.DUMMYFUNCTION("""COMPUTED_VALUE"""),"Ejemplos de pensamiento circular") -> Ejemplos de pensamiento circular
A36: 2.2 Recursos Educativos | B36: =IFERROR(__xludf.DUMMYFUNCTION("""COMPUTED_VALUE"""),"Unidad 2: Los sistemas abstractos diseñados") -> Unidad 2: Los sistemas abstractos diseñados | D36: =IFERROR(__xludf.DUMMYFUNCTION("""COMPUTED_VALUE"""),"Perspectiva de sistemas abstractos diseñados") -> Perspectiva de sistemas abstractos diseñados | F36: =IFERROR(__xludf.DUMMYFUNCTION("""COMPUTED_VALUE"""),"Ejemplos de retroalimentación") -> Ejemplos de retroalimentación
A38: Tipo de Recurso a utilizar | B38: Tipo | C38: Valor maximo recomendado en Minutos | D38: Tiempo Aproximado ( unicamente el valor de minutos ) | I38: Validacion
A39: Presentacion | B39: Obligatorio | C39: 30 | D39: 20 | I39: =IF(D39<=C39,"Correcto", "Corregir") -> Correcto
A40: Video | B40: Obligatorio | C40: 6 | D40: 5 | I40: =IF(D40<=C40,"Correcto", "Corregir") -> Correcto
A41: Lectura | B41: Optativo | C41: 10 | D41: 5 | I41: =IF(D41<=C41,"Correcto", "Corregir") -> Correcto
A42: Ejercicio Demostrativo | B42: Obligatorio | C42: 30 | D42: 10 | I42: =IF(D42<=C42,"Correcto", "Corregir") -> Correcto
A44: 3. Área de Habilidades (Saber Hacer) | G44: Tiempo Aproximado | H44: =B50 -> 45
G45: Tiene que estar en un rango de 30 a 50 minutos
A46: Actividad 1 (Obligatoria)
A47: Competencia que predomina en la actividad | B47: comprende los fundamentos conceptuales del pensamiento sistémico y la naturaleza de los sistemas de la realidad a través del estudio de teorías, modelos mentales y estructuras de retroalimentación para distinguir los sistemas naturales, físicos diseñados, abstractos diseñados y de actividad humana
A48: Tipo de Actividad | B48: Ejercicio practico
A49: Ponderación | B49: 1
...

Sheet S.5
B2: Diseño de la Sesión de Laboratorio
B4: Curso | C4: ='Diseño'!C4 -> 722 - Teoría de Sistemas 1
B5: Semana | C5: 5
B6: Tiempo | C6: =H10+H21+H44+H68 -> 110
B7: Ponderación | C7: =B49+B60 -> 1
B8: Validación de Tiempo | C8: =IF(H44<=0, "❌ ERROR: La Actividad 1 debe tener un tiempo mayor a 0.", IF(H21>60, "❌ ERROR: El 'Área de Conocimiento' no puede exceder los 60 min.", IF((H10+H21+H44)<100, "❌ ERROR: El tiempo total debe ser de al menos 100 min.", "✅ VALIDACIÓN CORRECTA"))) -> ✅ VALIDACIÓN CORRECTA
A10: 1. Área Actitudinal (Saber Ser) | G10: Tiempo Aproximado | H10: =B13 -> 5
G11: Tiene que estar en un rango de 3 a 5 minutos
A12: Nombre del Valor | B12: Estructura y Curiosidad Científica
A13: Tiempo Aproximado | B13: 5
A14: Descripcion
A15: Interés por desentrañar la estructura formal (partes y relaciones) que define el comportamiento de los sistemas.
A17: Como se relaciona con los conocimientos de la sesion y se aplicaria
A18: Se relaciona con los Fundamentos del pensamiento sistémico. Permite al estudiante Analizar que el comportamiento de un sistema se explica por su estructura (subsistemas, límites) y propiedades emergentes, preparando el terreno para el modelado formal de ingeniería.
A21: 2. Área Conocimiento (Saber) | G21: Tiempo Aproximado | H21: =SUM(D39:H42) -> 50
G22: No puede exceder los 60 minutos
A23: Competencia a desarrollar | B23: Analiza .. los principios basicos de la teoría de sistemas y su importancia en la vida mediante modelos sistémicos y recursos gráficos para analizar el funcionamiento, la estructura y las interacciones de los sistemas en distintos entornos tecnológicos
A24: Competencia a desarrollar
A26: 2.1 Contenido
A27: No. | B27: Unidad | D27: Tema | F27: Sub Tema
A28: 1 | B28: =IFERROR(__xludf.DUMMYFUNCTION("FILTER('Diseño'!D:D,'Diseño'!H:H=$C$5)"),"Unidad 2: Los sistemas abstractos diseñados") -> Unidad 2: Los sistemas abstractos diseñados | D28: =IFERROR(__xludf.DUMMYFUNCTION("FILTER('Diseño'!E:E,'Diseño'!H:H=$C$5)"),"Perspectiva de sistemas abstractos diseñados") -> Perspectiva de sistemas abstractos diseñados | F28: =IFERROR(__xludf.DUMMYFUNCTION("FILTER('Diseño'!F:F,'Diseño'!H:H=$C$5)"),"Conclusión de los modelos mentales diseñados") -> Conclusión de los modelos mentales diseñados
A29: 2 | B29: =IFERROR(__xludf.DUMMYFUNCTION("""COMPUTED_VALUE"""),"Unidad 3: Desarrollando el pensamiento sistémico complejo") -> Unidad 3: Desarrollando el pensamiento sistémico complejo | D29: =IFERROR(__xludf.DUMMYFUNCTION("""COMPUTED_VALUE"""),"Fundamentos del pensamiento sistémico") -> Fundamentos del pensamiento sistémico | F29: =IFERROR(__xludf.DUMMYFUNCTION("""COMPUTED_VALUE"""),"Concepto de sistema") -> Concepto de sistema
A30: 3 | B30: =IFERROR(__xludf.DUMMYFUNCTION("""COMPUTED_VALUE"""),"Unidad 3: Desarrollando el pensamiento sistémico complejo") -> Unidad 3: Desarrollando el pensamiento sistémico complejo | D30: =IFERROR(__xludf.DUMMYFUNCTION("""COMPUTED_VALUE"""),"Fundamentos del pensamiento sistémico") -> Fundamentos del pensamiento sistémico | F30: =IFERROR(__xludf.DUMMYFUNCTION("""COMPUTED_VALUE"""),"Estructura de los sistemas") -> Estructura de los sistemas
A31: 4 | B31: =IFERROR(__xludf.DUMMYFUNCTION("""COMPUTED_VALUE"""),"Unidad 3: Desarrollando el pensamiento sistémico complejo") -> Unidad 3: Desarrollando el pensamiento sistémico complejo | D31: =IFERROR(__xludf.DUMMYFUNCTION("""COMPUTED_VALUE"""),"Fundamentos del pensamiento sistémico") -> Fundamentos del pensamiento sistémico | F31: =IFERROR(__xludf.DUMMYFUNCTION("""COMPUTED_VALUE"""),"Subsistemas y suprasistemas") -> Subsistemas y suprasistemas
A32: 5 | B32: =IFERROR(__xludf.DUMMYFUNCTION("""COMPUTED_VALUE"""),"Unidad 3: Desarrollando el pensamiento sistémico complejo") -> Unidad 3: Desarrollando el pensamiento sistémico complejo | D32: =IFERROR(__xludf.DUMMYFUNCTION("""COMPUTED_VALUE"""),"Fundamentos del pensamiento sistémico") -> Fundamentos del pensamiento sistémico | F32: =IFERROR(__xludf.DUMMYFUNCTION("""COMPUTED_VALUE"""),"Sinergia y emergencia en sistemas") -> Sinergia y emergencia en sistemas
A33: 6 | B33: =IFERROR(__xludf.DUMMYFUNCTION("""COMPUTED_VALUE"""),"Unidad 3: Desarrollando el pensamiento sistémico complejo") -> Unidad 3: Desarrollando el pensamiento sistémico complejo | D33: =IFERROR(__xludf.DUMMYFUNCTION("""COMPUTED_VALUE"""),"Fundamentos del pensamiento sistémico") -> Fundamentos del pensamiento sistémico | F33: =IFERROR(__xludf.DUMMYFUNCTION("""COMPUTED_VALUE"""),"Complejidad sistémica") -> Complejidad sistémica
A34: 7 | B34: =IFERROR(__xludf.DUMMYFUNCTION("""COMPUTED_VALUE"""),"Unidad 3: Desarrollando el pensamiento sistémico complejo") -> Unidad 3: Desarrollando el pensamiento sistémico complejo | D34: =IFERROR(__xludf.DUMMYFUNCTION("""COMPUTED_VALUE"""),"Fundamentos del pensamiento sistémico") -> Fundamentos del pensamiento sistémico | F34: =IFERROR(__xludf.DUMMYFUNCTION("""COMPUTED_VALUE"""),"El universo como conjunto de sistemas") -> El universo como conjunto de sistemas
B35: =IFERROR(__xludf.DUMMYFUNCTION("""COMPUTED_VALUE"""),"Unidad 3: Desarrollando el pensamiento sistémico complejo") -> Unidad 3: Desarrollando el pensamiento sistémico complejo | D35: =IFERROR(__xludf.DUMMYFUNCTION("""COMPUTED_VALUE"""),"Fundamentos del pensamiento sistémico") -> Fundamentos del pensamiento sistémico | F35: =IFERROR(__xludf.DUMMYFUNCTION("""COMPUTED_VALUE"""),"Ejemplos de sistemas naturales") -> Ejemplos de sistemas naturales
A36: 2.2 Recursos Educativos | B36: =IFERROR(__xludf.DUMMYFUNCTION("""COMPUTED_VALUE"""),"Unidad 3: Desarrollando el pensamiento sistémico complejo") -> Unidad 3: Desarrollando el pensamiento sistémico complejo | D36: =IFERROR(__xludf.DUMMYFUNCTION("""COMPUTED_VALUE"""),"Clasificación de sistemas") -> Clasificación de sistemas | F36: =IFERROR(__xludf.DUMMYFUNCTION("""COMPUTED_VALUE"""),"Sistemas físicos diseñados") -> Sistemas físicos diseñados
A38: Tipo de Recurso a utilizar | B38: Tipo | C38: Valor maximo recomendado en Minutos | D38: Tiempo Aproximado ( unicamente el valor de minutos ) | I38: Validacion
A39: Presentacion | B39: Obligatorio | C39: 30 | D39: 25 | I39: =IF(D39<=C39,"Correcto", "Corregir") -> Correcto
A40: Video | B40: Obligatorio | C40: 6 | D40: 5 | I40: =IF(D40<=C40,"Correcto", "Corregir") -> Correcto
A41: Lectura | B41: Optativo | C41: 10 | D41: 5 | I41: =IF(D41<=C41,"Correcto", "Corregir") -> Correcto
A42: Ejercicio Demostrativo | B42: Obligatorio | C42: 30 | D42: 15 | I42: =IF(D42<=C42,"Correcto", "Corregir") -> Correcto
A44: 3. Área de Habilidades (Saber Hacer) | G44: Tiempo Aproximado | H44: =B50 -> 45
G45: Tiene que estar en un rango de 30 a 50 minutos
A46: Actividad 1 (Obligatoria)
A47: Competencia que predomina en la actividad | B47: Analiza .. los principios basicos de la teoría de sistemas y su importancia en la vida mediante modelos sistémicos y recursos gráficos para analizar el funcionamiento, la estructura y las interacciones de los sistemas en distintos entornos tecnológicos
A48: Tipo de Actividad | B48: Analisis
A49: Ponderación | B49: 1
...

Sheet S.6
B2: Diseño de la Sesión de Laboratorio
B4: Curso | C4: ='Diseño'!C4 -> 722 - Teoría de Sistemas 1
B5: Semana | C5: 6
B6: Tiempo | C6: =H10+H21+H44+H68 -> 100
B7: Ponderación | C7: =B49+B60 -> 1
B8: Validación de Tiempo | C8: =IF(H44<=0, "❌ ERROR: La Actividad 1 debe tener un tiempo mayor a 0.", IF(H21>60, "❌ ERROR: El 'Área de Conocimiento' no puede exceder los 60 min.", IF((H10+H21+H44)<100, "❌ ERROR: El tiempo total debe ser de al menos 100 min.", "✅ VALIDACIÓN CORRECTA"))) -> ❌ ERROR: El tiempo total debe ser de al menos 100 min.
A10: 1. Área Actitudinal (Saber Ser) | G10: Tiempo Aproximado | H10: =B13 -> 5
G11: Tiene que estar en un rango de 3 a 5 minutos
A12: Nombre del Valor | B12: Vision Profunda
A13: Tiempo Aproximado | B13: 5
A14: Descripcion
A15: Tendencia a buscar las causas estructurales y los patrones, y no conformarse con la explicación superficial de los eventos.
A17: Como se relaciona con los conocimientos de la sesion y se aplicaria
A18: Se relaciona directamente con el Modelo del Iceberg. Fomenta que el estudiante Identifique los patrones y estructuras (debajo de la superficie) para ir más allá de los eventos (la punta del iceberg), un paso crucial en el análisis sistémico.
A21: 2. Área Conocimiento (Saber) | G21: Tiempo Aproximado | H21: =SUM(D39:H42) -> 55
G22: No puede exceder los 60 minutos
A23: Competencia a desarrollar | B23: Analiza .. los principios basicos de la teoría de sistemas y su importancia en la vida mediante modelos sistémicos y recursos gráficos para analizar el funcionamiento, la estructura y las interacciones de los sistemas en distintos entornos tecnológicos
A24: Competencia a desarrollar | B24: identifica los conceptos fundamentales de la teoría de sistemas y del pensamiento sistémico mediante la revisión de definiciones para reconocer los elementos esenciales en el análisis y modelación de sistemas
A26: 2.1 Contenido
A27: No. | B27: Unidad | D27: Tema | F27: Sub Tema
A28: 1 | B28: =IFERROR(__xludf.DUMMYFUNCTION("FILTER('Diseño'!D:D,'Diseño'!H:H=$C$5)"),"Unidad 3: Desarrollando el pensamiento sistémico complejo") -> Unidad 3: Desarrollando el pensamiento sistémico complejo | D28: =IFERROR(__xludf.DUMMYFUNCTION("FILTER('Diseño'!E:E,'Diseño'!H:H=$C$5)"),"Clasificación de sistemas") -> Clasificación de sistemas | F28: =IFERROR(__xludf.DUMMYFUNCTION("FILTER('Diseño'!F:F,'Diseño'!H:H=$C$5)"),"Sistemas abstractos diseñados") -> Sistemas abstractos diseñados
A29: 2 | B29: =IFERROR(__xludf.DUMMYFUNCTION("""COMPUTED_VALUE"""),"Unidad 3: Desarrollando el pensamiento sistémico complejo") -> Unidad 3: Desarrollando el pensamiento sistémico complejo | D29: =IFERROR(__xludf.DUMMYFUNCTION("""COMPUTED_VALUE"""),"Clasificación de sistemas") -> Clasificación de sistemas | F29: =IFERROR(__xludf.DUMMYFUNCTION("""COMPUTED_VALUE"""),"Sistemas de actividad humana") -> Sistemas de actividad humana
A30: 3 | B30: =IFERROR(__xludf.DUMMYFUNCTION("""COMPUTED_VALUE"""),"Unidad 3: Desarrollando el pensamiento sistémico complejo") -> Unidad 3: Desarrollando el pensamiento sistémico complejo | D30: =IFERROR(__xludf.DUMMYFUNCTION("""COMPUTED_VALUE"""),"Clasificación de sistemas") -> Clasificación de sistemas | F30: =IFERROR(__xludf.DUMMYFUNCTION("""COMPUTED_VALUE"""),"Diferencias entre sistemas naturales y diseñados") -> Diferencias entre sistemas naturales y diseñados
A31: 4 | B31: =IFERROR(__xludf.DUMMYFUNCTION("""COMPUTED_VALUE"""),"Unidad 3: Desarrollando el pensamiento sistémico complejo") -> Unidad 3: Desarrollando el pensamiento sistémico complejo | D31: =IFERROR(__xludf.DUMMYFUNCTION("""COMPUTED_VALUE"""),"Clasificación de sistemas") -> Clasificación de sistemas | F31: =IFERROR(__xludf.DUMMYFUNCTION("""COMPUTED_VALUE"""),"Sistemas complejos adaptativos") -> Sistemas complejos adaptativos
A32: 5 | B32: =IFERROR(__xludf.DUMMYFUNCTION("""COMPUTED_VALUE"""),"Unidad 3: Desarrollando el pensamiento sistémico complejo") -> Unidad 3: Desarrollando el pensamiento sistémico complejo | D32: =IFERROR(__xludf.DUMMYFUNCTION("""COMPUTED_VALUE"""),"Clasificación de sistemas") -> Clasificación de sistemas | F32: =IFERROR(__xludf.DUMMYFUNCTION("""COMPUTED_VALUE"""),"Características de sistemas de actividad humana") -> Características de sistemas de actividad humana
A33: 6 | B33: =IFERROR(__xludf.DUMMYFUNCTION("""COMPUTED_VALUE"""),"Unidad 3: Desarrollando el pensamiento sistémico complejo") -> Unidad 3: Desarrollando el pensamiento sistémico complejo | D33: =IFERROR(__xludf.DUMMYFUNCTION("""COMPUTED_VALUE"""),"Clasificación de sistemas") -> Clasificación de sistemas | F33: =IFERROR(__xludf.DUMMYFUNCTION("""COMPUTED_VALUE"""),"Ejemplos de interacciones entre sistemas") -> Ejemplos de interacciones entre sistemas
A34: 7 | B34: =IFERROR(__xludf.DUMMYFUNCTION("""COMPUTED_VALUE"""),"Unidad 3: Desarrollando el pensamiento sistémico complejo") -> Unidad 3: Desarrollando el pensamiento sistémico complejo | D34: =IFERROR(__xludf.DUMMYFUNCTION("""COMPUTED_VALUE"""),"Niveles de perspectiva") -> Niveles de perspectiva | F34: =IFERROR(__xludf.DUMMYFUNCTION("""COMPUTED_VALUE"""),"Modelo del iceberg") -> Modelo del iceberg
B35: =IFERROR(__xludf.DUMMYFUNCTION("""COMPUTED_VALUE"""),"Unidad 3: Desarrollando el pensamiento sistémico complejo") -> Unidad 3: Desarrollando el pensamiento sistémico complejo | D35: =IFERROR(__xludf.DUMMYFUNCTION("""COMPUTED_VALUE"""),"Niveles de perspectiva") -> Niveles de perspectiva | F35: =IFERROR(__xludf.DUMMYFUNCTION("""COMPUTED_VALUE"""),"Interpretación de niveles de percepción") -> Interpretación de niveles de percepción
A36: 2.2 Recursos Educativos | B36: =IFERROR(__xludf.DUMMYFUNCTION("""COMPUTED_VALUE"""),"Unidad 3: Desarrollando el pensamiento sistémico complejo") -> Unidad 3: Desarrollando el pensamiento sistémico complejo | D36: =IFERROR(__xludf.DUMMYFUNCTION("""COMPUTED_VALUE"""),"Niveles de perspectiva") -> Niveles de perspectiva | F36: =IFERROR(__xludf.DUMMYFUNCTION("""COMPUTED_VALUE"""),"Impacto de la percepción en el pensamiento sistémico") -> Impacto de la percepción en el pensamiento sistémico
B37: =IFERROR(__xludf.DUMMYFUNCTION("""COMPUTED_VALUE"""),"Unidad 3: Desarrollando el pensamiento sistémico complejo") -> Unidad 3: Desarrollando el pensamiento sistémico complejo | D37: =IFERROR(__xludf.DUMMYFUNCTION("""COMPUTED_VALUE"""),"Niveles de perspectiva") -> Niveles de perspectiva | F37: =IFERROR(__xludf.DUMMYFUNCTION("""COMPUTED_VALUE"""),"Ejemplos de interpretación de sistemas") -> Ejemplos de interpretación de sistemas
A38: Tipo de Recurso a utilizar | B38: Tipo | C38: Valor maximo recomendado en Minutos | D38: Tiempo Aproximado ( unicamente el valor de minutos ) | I38: Validacion
A39: Presentacion | B39: Obligatorio | C39: 30 | D39: 15 | I39: =IF(D39<=C39,"Correcto", "Corregir") -> Correcto
A40: Video | B40: Obligatorio | C40: 6 | D40: 5 | I40: =IF(D40<=C40,"Correcto", "Corregir") -> Correcto
A41: Lectura | B41: Optativo | C41: 10 | D41: 5 | I41: =IF(D41<=C41,"Correcto", "Corregir") -> Correcto
A42: Ejercicio Demostrativo | B42: Obligatorio | C42: 30 | D42: 30 | I42: =IF(D42<=C42,"Correcto", "Corregir") -> Correcto
A44: 3. Área de Habilidades (Saber Hacer) | G44: Tiempo Aproximado | H44: =B50 -> 30
G45: Tiene que estar en un rango de 30 a 50 minutos
A46: Actividad 1 (Obligatoria)
A47: Competencia que predomina en la actividad | B47: Analiza .. los principios basicos de la teoría de sistemas y su importancia en la vida mediante modelos sistémicos y recursos gráficos para analizar el funcionamiento, la estructura y las interacciones de los sistemas en distintos entornos tecnológicos
A48: Tipo de Actividad | B48: Analisis
...

Sheet S.7
B2: Diseño de la Sesión de Laboratorio
B4: Curso | C4: ='Diseño'!C4 -> 722 - Teoría de Sistemas 1
B5: Semana | C5: 7
B6: Tiempo | C6: =H10+H21+H44+H68 -> 100
B7: Ponderación | C7: =B49+B60 -> 1
B8: Validación de Tiempo | C8: =IF(H44<=0, "❌ ERROR: La Actividad 1 debe tener un tiempo mayor a 0.", IF(H21>60, "❌ ERROR: El 'Área de Conocimiento' no puede exceder los 60 min.", IF((H10+H21+H44)<100, "❌ ERROR: El tiempo total debe ser de al menos 100 min.", "✅ VALIDACIÓN CORRECTA"))) -> ❌ ERROR: El tiempo total debe ser de al menos 100 min.
A10: 1. Área Actitudinal (Saber Ser) | G10: Tiempo Aproximado | H10: =B13 -> 5
G11: Tiene que estar en un rango de 3 a 5 minutos
A12: Nombre del Valor | B12: Intención y Práctica
A13: Tiempo Aproximado | B13: 5
A14: Descripcion
A15: La disciplina consciente para adoptar las prácticas sistémicas en la vida diaria.
A17: Como se relaciona con los conocimientos de la sesion y se aplicaria
A18: Se relaciona con los Hábitos de un Pensador Sistémico. Fomenta que el estudiante Comprenda que el pensamiento sistémico no es solo conocimiento, sino un conjunto de prácticas intencionales (hábitos) que mejoran la toma de decisiones a largo plazo.
A21: 2. Área Conocimiento (Saber) | G21: Tiempo Aproximado | H21: =SUM(D39:H42) -> 50
G22: No puede exceder los 60 minutos
A23: Competencia a desarrollar | B23: comprende los fundamentos conceptuales del pensamiento sistémico y la naturaleza de los sistemas de la realidad a través del estudio de teorías, modelos mentales y estructuras de retroalimentación para distinguir los sistemas naturales, físicos diseñados, abstractos diseñados y de actividad humana
A24: Competencia a desarrollar
A26: 2.1 Contenido
A27: No. | B27: Unidad | D27: Tema | F27: Sub Tema
A28: 1 | B28: =IFERROR(__xludf.DUMMYFUNCTION("FILTER('Diseño'!D:D,'Diseño'!H:H=$C$5)"),"Unidad 3: Desarrollando el pensamiento sistémico complejo") -> Unidad 3: Desarrollando el pensamiento sistémico complejo | D28: =IFERROR(__xludf.DUMMYFUNCTION("FILTER('Diseño'!E:E,'Diseño'!H:H=$C$5)"),"Niveles de perspectiva") -> Niveles de perspectiva | F28: =IFERROR(__xludf.DUMMYFUNCTION("FILTER('Diseño'!F:F,'Diseño'!H:H=$C$5)"),"Cambio de perspectiva en análisis sistémico") -> Cambio de perspectiva en análisis sistémico
A29: 2 | B29: =IFERROR(__xludf.DUMMYFUNCTION("""COMPUTED_VALUE"""),"Unidad 3: Desarrollando el pensamiento sistémico complejo") -> Unidad 3: Desarrollando el pensamiento sistémico complejo | D29: =IFERROR(__xludf.DUMMYFUNCTION("""COMPUTED_VALUE"""),"Niveles de perspectiva") -> Niveles de perspectiva | F29: =IFERROR(__xludf.DUMMYFUNCTION("""COMPUTED_VALUE"""),"Impacto del cambio de nivel de percepción") -> Impacto del cambio de nivel de percepción
A30: 3 | B30: =IFERROR(__xludf.DUMMYFUNCTION("""COMPUTED_VALUE"""),"Unidad 3: Desarrollando el pensamiento sistémico complejo") -> Unidad 3: Desarrollando el pensamiento sistémico complejo | D30: =IFERROR(__xludf.DUMMYFUNCTION("""COMPUTED_VALUE"""),"Niveles de perspectiva") -> Niveles de perspectiva | F30: =IFERROR(__xludf.DUMMYFUNCTION("""COMPUTED_VALUE"""),"Ejemplos de interacción entre niveles de perspectiva") -> Ejemplos de interacción entre niveles de perspectiva
A31: 4 | B31: =IFERROR(__xludf.DUMMYFUNCTION("""COMPUTED_VALUE"""),"Unidad 3: Desarrollando el pensamiento sistémico complejo") -> Unidad 3: Desarrollando el pensamiento sistémico complejo | D31: =IFERROR(__xludf.DUMMYFUNCTION("""COMPUTED_VALUE"""),"Hábitos de un pensador sistémico") -> Hábitos de un pensador sistémico | F31: =IFERROR(__xludf.DUMMYFUNCTION("""COMPUTED_VALUE"""),"Introducción a los hábitos de un pensador sistémico") -> Introducción a los hábitos de un pensador sistémico
A32: 5 | B32: =IFERROR(__xludf.DUMMYFUNCTION("""COMPUTED_VALUE"""),"Unidad 3: Desarrollando el pensamiento sistémico complejo") -> Unidad 3: Desarrollando el pensamiento sistémico complejo | D32: =IFERROR(__xludf.DUMMYFUNCTION("""COMPUTED_VALUE"""),"Hábitos de un pensador sistémico") -> Hábitos de un pensador sistémico | F32: =IFERROR(__xludf.DUMMYFUNCTION("""COMPUTED_VALUE"""),"Ejemplos de hábitos de pensamiento sistémico") -> Ejemplos de hábitos de pensamiento sistémico
A33: 6 | B33: =IFERROR(__xludf.DUMMYFUNCTION("""COMPUTED_VALUE"""),"Unidad 3: Desarrollando el pensamiento sistémico complejo") -> Unidad 3: Desarrollando el pensamiento sistémico complejo | D33: =IFERROR(__xludf.DUMMYFUNCTION("""COMPUTED_VALUE"""),"Hábitos de un pensador sistémico") -> Hábitos de un pensador sistémico | F33: =IFERROR(__xludf.DUMMYFUNCTION("""COMPUTED_VALUE"""),"Aplicación de hábitos en la vida diaria") -> Aplicación de hábitos en la vida diaria
A34: 7 | B34: =IFERROR(__xludf.DUMMYFUNCTION("""COMPUTED_VALUE"""),"Unidad 3: Desarrollando el pensamiento sistémico complejo") -> Unidad 3: Desarrollando el pensamiento sistémico complejo | D34: =IFERROR(__xludf.DUMMYFUNCTION("""COMPUTED_VALUE"""),"Hábitos de un pensador sistémico") -> Hábitos de un pensador sistémico | F34: =IFERROR(__xludf.DUMMYFUNCTION("""COMPUTED_VALUE"""),"Relación entre hábitos y toma de decisiones") -> Relación entre hábitos y toma de decisiones
